2022-03-30 20:48:49,304:INFO:Lecture d'un fichier json
2022-03-30 20:48:49,305:ERROR:Exception occurred
Traceback (most recent call last):
  File "elt.py", line 24, in read_file
    df = pd.read_json(input_file_name)
  File "/home/konan/Documents/projets/proj-data-lambda/pdl_env/lib/python3.8/site-packages/pandas/util/_decorators.py", line 207, in wrapper
    return func(*args, **kwargs)
  File "/home/konan/Documents/projets/proj-data-lambda/pdl_env/lib/python3.8/site-packages/pandas/util/_decorators.py", line 311, in wrapper
    return func(*args, **kwargs)
  File "/home/konan/Documents/projets/proj-data-lambda/pdl_env/lib/python3.8/site-packages/pandas/io/json/_json.py", line 612, in read_json
    return json_reader.read()
  File "/home/konan/Documents/projets/proj-data-lambda/pdl_env/lib/python3.8/site-packages/pandas/io/json/_json.py", line 746, in read
    obj = self._get_object_parser(self.data)
  File "/home/konan/Documents/projets/proj-data-lambda/pdl_env/lib/python3.8/site-packages/pandas/io/json/_json.py", line 768, in _get_object_parser
    obj = FrameParser(json, **kwargs).parse()
  File "/home/konan/Documents/projets/proj-data-lambda/pdl_env/lib/python3.8/site-packages/pandas/io/json/_json.py", line 880, in parse
    self._parse_no_numpy()
  File "/home/konan/Documents/projets/proj-data-lambda/pdl_env/lib/python3.8/site-packages/pandas/io/json/_json.py", line 1133, in _parse_no_numpy
    loads(json, precise_float=self.precise_float), dtype=None
ValueError: Unexpected character found when decoding array value (1)
